<sdf version='1.7'>
  <model name='go2'>
    <link name='body'>
      <pose frame=''>0 0 0 0 -0 0</pose>
      <inertial>
        <pose frame=''>0.021109 0 -0.005365 0 -0 0</pose>
        <mass>6.922</mass>
        <inertia>
          <ixx>0.02458</ixx>
          <ixy>0.00012166</ixy>
          <ixz>0.00148501</ixz>
          <iyy>0.0981775</iyy>
          <iyz>-3.12e-05</iyz>
          <izz>0.1071</izz>
        </inertia>
      </inertial>
      <collision name='body_collision'>
        <pose frame=''>0 0 0 0 -0 0</pose>
        <geometry>
          <box>
            <size>0.3762 0.0935 0.114</size>
          </box>
        </geometry>
        <surface>
          <contact>
            <ode/>
          </contact>
          <friction>
            <ode/>
          </friction>
        </surface>
      </collision>
      <collision name='body_fixed_joint_lump__imu_link_collision_1'>
        <pose frame=''>0 0 0 0 -0 0</pose>
        <geometry>
          <box>
            <size>0.001 0.001 0.001</size>
          </box>
        </geometry>
        <surface>
          <contact>
            <ode/>
          </contact>
          <friction>
            <ode>
              <mu>0.2</mu>
              <mu2>0.2</mu2>
            </ode>
          </friction>
        </surface>
      </collision>
      <visual name='body_visual'>
        <pose frame=''>0 0 0 0 -0 0</pose>
        <geometry>
          <box>
            <size>0.001 0.001 0.001</size>
          </box>
        </geometry>
        <material>
          <script>
            <name>Gazebo/Green</name>
            <uri>file://media/materials/scripts/gazebo.material</uri>
          </script>
        </material>
      </visual>
      <visual name='body_visual_visual_1'>
        <pose frame=''>0 0 0 0 -0 0</pose>
        <geometry>
          <mesh>
            <scale>1 1 1</scale>
            <uri>file:///home/lunarlab/Desktop/quadruped_sim_ws/src/quad-sdk/quad_simulator/go2_description/meshes/trunk.dae</uri>
          </mesh>
        </geometry>
        <material>
          <script>
            <name>Gazebo/Green</name>
            <uri>file://media/materials/scripts/gazebo.material</uri>
          </script>
        </material>
      </visual>
      <visual name='body_fixed_joint_lump__imu_link_visual_2'>
        <pose frame=''>0 0 0 0 -0 0</pose>
        <geometry>
          <box>
            <size>0.001 0.001 0.001</size>
          </box>
        </geometry>
        <material>
          <script>
            <name>Gazebo/Red</name>
            <uri>file://media/materials/scripts/gazebo.material</uri>
          </script>
        </material>
      </visual>
      <gravity>1</gravity>
      <gravity>1</gravity>
      <sensor name='imu_sensor' type='imu'>
        <always_on>1</always_on>
        <update_rate>1000</update_rate>
        <visualize>1</visualize>
        <topic>__default_topic__</topic>
        <plugin name='imu_plugin' filename='libgazebo_ros_imu_sensor.so'>
          <topicName>trunk_imu</topicName>
          <bodyName>imu_link</bodyName>
          <updateRateHZ>1000.0</updateRateHZ>
          <gaussianNoise>0.0</gaussianNoise>
          <xyzOffset>0 0 0</xyzOffset>
          <rpyOffset>0 0 0</rpyOffset>
          <frameName>imu_link</frameName>
        </plugin>
        <pose frame=''>0 0 0 0 -0 0</pose>
      </sensor>
    </link>
    
    <link name='hip2'>
      <pose relative_to='10'>0 0 0 0 -0 0</pose>
      <inertial>
        <pose frame=''>-0.0054 -0.00194 -0.000105 0 -0 0</pose>
        <mass>0.678</mass>
        <inertia>
          <ixx>0.00048</ixx>
          <ixy>3.01e-06</ixy>
          <ixz>1.11e-06</ixz>
          <iyy>0.000884</iyy>
          <iyz>1.42e-06</iyz>
          <izz>0.000596</izz>
        </inertia>
      </inertial>
      <collision name='hip2_collision'>
        <pose frame=''>0 -0.0955 0 1.5708 -0 0</pose>
        <geometry>
          <cylinder>
            <length>0.04</length>
            <radius>0.046</radius>
          </cylinder>
        </geometry>
        <surface>
          <contact>
            <ode/>
          </contact>
          <friction>
            <ode>
              <mu>0.2</mu>
              <mu2>0.2</mu2>
            </ode>
          </friction>
        </surface>
      </collision>
      <visual name='hip2_visual_visual'>
        <pose frame=''>0 0 0 3.14159 -0 0</pose>
        <geometry>
          <mesh>
            <scale>1 1 1</scale>
            <uri>model://go2_description/meshes/hip.dae</uri>
          </mesh>
        </geometry>
        <material>
          <script>
            <name>Gazebo/DarkGrey</name>
            <uri>file://media/materials/scripts/gazebo.material</uri>
          </script>
        </material>
      </visual>
    </link>
    <joint name='10' type='revolute'>
      <pose relative_to='body'>0.1934 -0.0465 0 0 -0 0</pose>
      <parent>body</parent>
      <child>hip2</child>
      <physics>
        <provide_feedback>true</provide_feedback>
      </physics>
      <axis>
        <xyz>1 0 0</xyz>
        <limit>
          <lower>-1.0472</lower>
          <upper>1.0472</upper>
          <effort>23.7</effort>
          <velocity>30.1</velocity>
        </limit>
        <dynamics>
          <damping>0</damping>
          <friction>0</friction>
          <spring_reference>0</spring_reference>
          <spring_stiffness>0</spring_stiffness>
        </dynamics>
      </axis>
    </joint>

    <link name='upper2'>
      <pose relative_to='4'>0 0 0 0 -0 0</pose>
      <inertial>
        <pose frame=''>-0.00374 0.0223 -0.0327 0 -0 0</pose>
        <mass>1.152</mass>
        <inertia>
          <ixx>0.00584</ixx>
          <ixy>-8.72e-05</ixy>
          <ixz>-0.000289</ixz>
          <iyy>0.0058</iyy>
          <iyz>-0.000808</iyz>
          <izz>0.00103</izz>
        </inertia>
      </inertial>
      <collision name='upper2_collision'>
        <pose frame=''>0 0 -0.1065 0 1.5708 0</pose>
        <geometry>
          <box>
            <size>0.213 0.0245 0.034</size>
          </box>
        </geometry>
        <surface>
          <contact>
            <ode>
              <kp>1e+06</kp>
              <kd>1</kd>
            </ode>
          </contact>
          <friction>
            <ode>
              <mu>0.2</mu>
              <mu2>0.2</mu2>
            </ode>
          </friction>
        </surface>
      </collision>
      <visual name='upper2_visual_visual'>
        <pose frame=''>0 0 0 0 -0 0</pose>
        <geometry>
          <mesh>
            <scale>1 1 1</scale>
            <uri>file:///home/lunarlab/Desktop/quadruped_sim_ws/src/quad-sdk/quad_simulator/go2_description/meshes/thigh_mirror.dae</uri>
          </mesh>
        </geometry>
        <material>
          <script>
            <name>Gazebo/DarkGrey</name>
            <uri>file://media/materials/scripts/gazebo.material</uri>
          </script>
        </material>
      </visual>
      <self_collide>0</self_collide>
    </link>

    <joint name='4' type='revolute'>
      <pose relative_to='hip2'>0 -0.0955 0 0 -0 0</pose>
      <parent>hip2</parent>
      <child>upper2</child>
      <physics>
        <provide_feedback>true</provide_feedback>
      </physics>
      <axis>
        <xyz>0 1 0</xyz>
        <limit>
          <lower>-1.5708</lower>
          <upper>3.4907</upper>
          <effort>23.7</effort>
          <velocity>30.1</velocity>
        </limit>
        <dynamics>
          <damping>0</damping>
          <friction>0</friction>
          <spring_reference>0</spring_reference>
          <spring_stiffness>0</spring_stiffness>
        </dynamics>
      </axis>
    </joint>
    
    <link name='lower2'>
      <pose relative_to='5'>0 0 0 0 -0 0</pose>
      <inertial>
        <pose frame=''>0.00548 -0.000975 -0.115 0 -0 0</pose>
        <mass>0.154</mass>
        <inertia>
          <ixx>0.00108</ixx>
          <ixy>3.4e-07</ixy>
          <ixz>1.72e-05</ixz>
          <iyy>0.0011</iyy>
          <iyz>8.28e-06</iyz>
          <izz>3.29e-05</izz>
        </inertia>
      </inertial>
      <collision name='lower2_collision'>
        <pose frame=''>0 0 -0.1065 0 1.5708 0</pose>
        <geometry>
          <box>
            <size>0.213 0.016 0.016</size>
          </box>
        </geometry>
        <surface>
          <contact>
            <ode/>
          </contact>
          <friction>
            <ode>
              <mu>0.2</mu>
              <mu2>0.2</mu2>
            </ode>
          </friction>
        </surface>
      </collision>
      <visual name='lower2_visual_visual'>
        <pose frame=''>0 0 0 0 -0 0</pose>
        <geometry>
          <mesh>
            <scale>1 1 1</scale>
            <uri>file:///home/lunarlab/Desktop/quadruped_sim_ws/src/quad-sdk/quad_simulator/go2_description/meshes/calf.dae</uri>
          </mesh>
        </geometry>
      </visual>
      <self_collide>0</self_collide>
    </link>

    <joint name='5' type='revolute'>
      <pose relative_to='upper2'>0 0 -0.213 0 -0 0</pose>
      <parent>upper2</parent>
      <child>lower2</child>
      <physics>
        <provide_feedback>true</provide_feedback>
      </physics>
      <axis>
        <xyz>0 1 0</xyz>
        <limit>
          <lower>-2.7227</lower>
          <upper>-0.83776</upper>
          <effort>35.55</effort>
          <velocity>20.06</velocity>
        </limit>
        <dynamics>
          <damping>0</damping>
          <friction>0</friction>
          <spring_reference>0</spring_reference>
          <spring_stiffness>0</spring_stiffness>
        </dynamics>
      </axis>
    </joint>

    <link name='toe2'>
      <pose relative_to='jtoe2'>0 0 0 0 -0 0</pose>
      <inertial>
        <pose frame=''>0 0 0 0 -0 0</pose>
        <mass>0.06</mass>
        <inertia>
          <ixx>9.6e-06</ixx>
          <ixy>0</ixy>
          <ixz>0</ixz>
          <iyy>9.6e-06</iyy>
          <iyz>0</iyz>
          <izz>9.6e-06</izz>
        </inertia>
      </inertial>
      <collision name='toe2_collision'>
        <pose frame=''>0 0 0 0 -0 0</pose>
        <geometry>
          <sphere>
            <radius>0.02</radius>
          </sphere>
        </geometry>
        <surface>
          <contact>
            <ode>
              <kp>1e+06</kp>
              <kd>1</kd>
            </ode>
          </contact>
          <friction>
            <ode>
              <mu>0.6</mu>
              <mu2>0.6</mu2>
            </ode>
          </friction>
        </surface>
      </collision>
      <visual name='toe2_visual_visual'>
        <pose frame=''>0 0 0 0 -0 0</pose>
        <geometry>
          <sphere>
            <radius>0.01</radius>
          </sphere>
        </geometry>
        <material>
          <script>
            <name>Gazebo/DarkGrey</name>
            <uri>file://media/materials/scripts/gazebo.material</uri>
          </script>
        </material>
      </visual>
      <sensor name='toe2_contact' type='contact'>
        <plugin name='toe2_plugin' filename='libgazebo_ros_bumper.so'>
          <alwaysOn>1</alwaysOn>
          <updateRate>500</updateRate>
          <bumperTopicName>gazebo/toe2_contact_state</bumperTopicName>
          <frameName>world</frameName>
        </plugin>
        <contact>
          <collision>toe2_collision</collision>
          <topic>__default_topic__</topic>
        </contact>
        <update_rate>500</update_rate>
      </sensor>
      <self_collide>0</self_collide>
    </link>


    <joint name='jtoe2' type='fixed'>
      <pose relative_to='lower2'>0 0 -0.213 0 -0 0</pose>
      <parent>lower2</parent>
      <child>toe2</child>
      <axis>
        <dynamics>
          <spring_reference>0</spring_reference>
          <spring_stiffness>0</spring_stiffness>
        </dynamics>
        <xyz>0 0 1</xyz>
        <limit>
          <lower>-1e+16</lower>
          <upper>1e+16</upper>
        </limit>
      </axis>
      <physics>
        <ode>
          <limit>
            <cfm>0</cfm>
            <erp>0.2</erp>
          </limit>
        </ode>
      </physics>
    </joint>
    
    <link name='hip3'>
      <pose relative_to='11'>0 0 0 0 -0 0</pose>
      <inertial>
        <pose frame=''>0.0054 -0.00194 -0.000105 0 -0 0</pose>
        <mass>0.678</mass>
        <inertia>
          <ixx>0.00048</ixx>
          <ixy>-3.01e-06</ixy>
          <ixz>-1.11e-06</ixz>
          <iyy>0.000884</iyy>
          <iyz>1.42e-06</iyz>
          <izz>0.000596</izz>
        </inertia>
      </inertial>
      <collision name='hip3_collision'>
        <pose frame=''>0 -0.0955 0 1.5708 -0 0</pose>
        <geometry>
          <cylinder>
            <length>0.04</length>
            <radius>0.046</radius>
          </cylinder>
        </geometry>
        <surface>
          <contact>
            <ode/>
          </contact>
          <friction>
            <ode>
              <mu>0.2</mu>
              <mu2>0.2</mu2>
            </ode>
          </friction>
        </surface>
      </collision>
      <visual name='hip3_visual_visual'>
        <pose frame=''>0 0 0 -0 0 3.14159</pose>
        <geometry>
          <mesh>
            <scale>1 1 1</scale>
            <uri>file:///home/lunarlab/Desktop/quadruped_sim_ws/src/quad-sdk/quad_simulator/go2_description/meshes/hip.dae</uri>
          </mesh>
        </geometry>
        <material>
          <script>
            <name>Gazebo/DarkGrey</name>
            <uri>file://media/materials/scripts/gazebo.material</uri>
          </script>
        </material>
      </visual>
    </link>

    <joint name='11' type='revolute'>
      <pose relative_to='body'>-0.1934 -0.0465 0 0 -0 0</pose>
      <parent>body</parent>
      <child>hip3</child>
      <physics>
        <provide_feedback>true</provide_feedback>
      </physics>
      <axis>
        <xyz>1 0 0</xyz>
        <limit>
          <lower>-1.0472</lower>
          <upper>1.0472</upper>
          <effort>23.7</effort>
          <velocity>30.1</velocity>
        </limit>
        <dynamics>
          <damping>0</damping>
          <friction>0</friction>
          <spring_reference>0</spring_reference>
          <spring_stiffness>0</spring_stiffness>
        </dynamics>
      </axis>
    </joint>
    
    <link name='upper3'>
      <pose relative_to='6'>0 0 0 0 -0 0</pose>
      <inertial>
        <pose frame=''>-0.00374 0.0223 -0.0327 0 -0 0</pose>
        <mass>1.152</mass>
        <inertia>
          <ixx>0.00584</ixx>
          <ixy>-8.72e-05</ixy>
          <ixz>-0.000289</ixz>
          <iyy>0.0058</iyy>
          <iyz>-0.000808</iyz>
          <izz>0.00103</izz>
        </inertia>
      </inertial>
      <collision name='upper3_collision'>
        <pose frame=''>0 0 -0.1065 0 1.5708 0</pose>
        <geometry>
          <box>
            <size>0.213 0.0245 0.034</size>
          </box>
        </geometry>
        <surface>
          <contact>
            <ode>
              <kp>1e+06</kp>
              <kd>1</kd>
            </ode>
          </contact>
          <friction>
            <ode>
              <mu>0.2</mu>
              <mu2>0.2</mu2>
            </ode>
          </friction>
        </surface>
      </collision>
      <visual name='upper3_visual_visual'>
        <pose frame=''>0 0 0 0 -0 0</pose>
        <geometry>
          <mesh>
            <scale>1 1 1</scale>
            <uri>file:///home/lunarlab/Desktop/quadruped_sim_ws/src/quad-sdk/quad_simulator/go2_description/meshes/thigh_mirror.dae</uri>
          </mesh>
        </geometry>
        <material>
          <script>
            <name>Gazebo/DarkGrey</name>
            <uri>file://media/materials/scripts/gazebo.material</uri>
          </script>
        </material>
      </visual>
      <self_collide>0</self_collide>
    </link>

    <joint name='6' type='revolute'>
      <pose relative_to='hip3'>0 -0.0955 0 0 -0 0</pose>
      <parent>hip3</parent>
      <child>upper3</child>
      <physics>
        <provide_feedback>true</provide_feedback>
      </physics>
      <axis>
        <xyz>0 1 0</xyz>
        <limit>
          <lower>-1.5708</lower>
          <upper>3.4907</upper>
          <effort>23.7</effort>
          <velocity>30.1</velocity>
        </limit>
        <dynamics>
          <damping>0</damping>
          <friction>0</friction>
          <spring_reference>0</spring_reference>
          <spring_stiffness>0</spring_stiffness>
        </dynamics>
      </axis>
    </joint>
    
    <link name='lower3'>
      <pose relative_to='7'>0 0 0 0 -0 0</pose>
      <inertial>
        <pose frame=''>0.00548 -0.000975 -0.115 0 -0 0</pose>
        <mass>0.154</mass>
        <inertia>
          <ixx>0.00108</ixx>
          <ixy>3.4e-07</ixy>
          <ixz>1.72e-05</ixz>
          <iyy>0.0011</iyy>
          <iyz>8.28e-06</iyz>
          <izz>3.29e-05</izz>
        </inertia>
      </inertial>
      <collision name='lower3_collision'>
        <pose frame=''>0 0 -0.1065 0 1.5708 0</pose>
        <geometry>
          <box>
            <size>0.213 0.016 0.016</size>
          </box>
        </geometry>
        <surface>
          <contact>
            <ode/>
          </contact>
          <friction>
            <ode>
              <mu>0.2</mu>
              <mu2>0.2</mu2>
            </ode>
          </friction>
        </surface>
      </collision>
      <visual name='lower3_visual_visual'>
        <pose frame=''>0 0 0 0 -0 0</pose>
        <geometry>
          <mesh>
            <scale>1 1 1</scale>
            <uri>file:///home/lunarlab/Desktop/quadruped_sim_ws/src/quad-sdk/quad_simulator/go2_description/meshes/calf.dae</uri>
          </mesh>
        </geometry>
      </visual>
      <self_collide>0</self_collide>
    </link>

    <joint name='7' type='revolute'>
      <pose relative_to='upper3'>0 0 -0.213 0 -0 0</pose>
      <parent>upper3</parent>
      <child>lower3</child>
      <physics>
        <provide_feedback>true</provide_feedback>
      </physics>
      <axis>
        <xyz>0 1 0</xyz>
        <limit>
          <lower>-2.7227</lower>
          <upper>-0.83776</upper>
          <effort>35.55</effort>
          <velocity>20.06</velocity>
        </limit>
        <dynamics>
          <damping>0</damping>
          <friction>0</friction>
          <spring_reference>0</spring_reference>
          <spring_stiffness>0</spring_stiffness>
        </dynamics>
      </axis>
    </joint>
    
    <link name='toe3'>
      <pose relative_to='jtoe3'>0 0 0 0 -0 0</pose>
      <inertial>
        <pose frame=''>0 0 0 0 -0 0</pose>
        <mass>0.06</mass>
        <inertia>
          <ixx>9.6e-06</ixx>
          <ixy>0</ixy>
          <ixz>0</ixz>
          <iyy>9.6e-06</iyy>
          <iyz>0</iyz>
          <izz>9.6e-06</izz>
        </inertia>
      </inertial>
      <collision name='toe3_collision'>
        <pose frame=''>0 0 0 0 -0 0</pose>
        <geometry>
          <sphere>
            <radius>0.02</radius>
          </sphere>
        </geometry>
        <surface>
          <contact>
            <ode>
              <kp>1e+06</kp>
              <kd>1</kd>
            </ode>
          </contact>
          <friction>
            <ode>
              <mu>0.6</mu>
              <mu2>0.6</mu2>
            </ode>
          </friction>
        </surface>
      </collision>
      <visual name='toe3_visual_visual'>
        <pose frame=''>0 0 0 0 -0 0</pose>
        <geometry>
          <sphere>
            <radius>0.01</radius>
          </sphere>
        </geometry>
        <material>
          <script>
            <name>Gazebo/DarkGrey</name>
            <uri>file://media/materials/scripts/gazebo.material</uri>
          </script>
        </material>
      </visual>
      <sensor name='toe3_contact' type='contact'>
        <plugin name='toe3_plugin' filename='libgazebo_ros_bumper.so'>
          <alwaysOn>1</alwaysOn>
          <updateRate>500</updateRate>
          <bumperTopicName>gazebo/toe3_contact_state</bumperTopicName>
          <frameName>world</frameName>
        </plugin>
        <contact>
          <collision>toe3_collision</collision>
          <topic>__default_topic__</topic>
        </contact>
        <update_rate>500</update_rate>
      </sensor>
      <self_collide>0</self_collide>
    </link>

    <joint name='jtoe3' type='fixed'>
      <pose relative_to='lower3'>0 0 -0.213 0 -0 0</pose>
      <parent>lower3</parent>
      <child>toe3</child>
      <axis>
        <dynamics>
          <spring_reference>0</spring_reference>
          <spring_stiffness>0</spring_stiffness>
        </dynamics>
        <xyz>0 0 1</xyz>
        <limit>
          <lower>-1e+16</lower>
          <upper>1e+16</upper>
        </limit>
      </axis>
      <physics>
        <ode>
          <limit>
            <cfm>0</cfm>
            <erp>0.2</erp>
          </limit>
        </ode>
      </physics>
    </joint>
    
    <link name='hip0'>
      <pose relative_to='8'>0 0 0 0 -0 0</pose>
      <inertial>
        <pose frame=''>-0.0054 0.00194 -0.000105 0 -0 0</pose>
        <mass>0.678</mass>
        <inertia>
          <ixx>0.00048</ixx>
          <ixy>-3.01e-06</ixy>
          <ixz>1.11e-06</ixz>
          <iyy>0.000884</iyy>
          <iyz>-1.42e-06</iyz>
          <izz>0.000596</izz>
        </inertia>
      </inertial>
      <collision name='hip0_collision'>
        <pose frame=''>0 0.0955 0 1.5708 -0 0</pose>
        <geometry>
          <cylinder>
            <length>0.04</length>
            <radius>0.046</radius>
          </cylinder>
        </geometry>
        <surface>
          <contact>
            <ode/>
          </contact>
          <friction>
            <ode>
              <mu>0.2</mu>
              <mu2>0.2</mu2>
            </ode>
          </friction>
        </surface>
      </collision>
      <visual name='hip0_visual_visual'>
        <pose frame=''>0 0 0 0 -0 0</pose>
        <geometry>
          <mesh>
            <scale>1 1 1</scale>
            <uri>file:///home/lunarlab/Desktop/quadruped_sim_ws/src/quad-sdk/quad_simulator/go2_description/meshes/hip.dae</uri>
          </mesh>
        </geometry>
        <material>
          <script>
            <name>Gazebo/DarkGrey</name>
            <uri>file://media/materials/scripts/gazebo.material</uri>
          </script>
        </material>
      </visual>
    </link>

    <joint name='8' type='revolute'>
      <pose relative_to='body'>0.1934 0.0465 0 0 -0 0</pose>
      <parent>body</parent>
      <child>hip0</child>
      <physics>
        <provide_feedback>true</provide_feedback>
      </physics>
      <axis>
        <xyz>1 0 0</xyz>
        <limit>
          <lower>-1.0472</lower>
          <upper>1.0472</upper>
          <effort>23.7</effort>
          <velocity>30.1</velocity>
        </limit>
        <dynamics>
          <damping>0</damping>
          <friction>0</friction>
          <spring_reference>0</spring_reference>
          <spring_stiffness>0</spring_stiffness>
        </dynamics>
      </axis>
    </joint>
    
    <link name='upper0'>
      <pose relative_to='0'>0 0 0 0 -0 0</pose>
      <inertial>
        <pose frame=''>-0.00374 -0.0223 -0.0327 0 -0 0</pose>
        <mass>1.152</mass>
        <inertia>
          <ixx>0.00584</ixx>
          <ixy>8.72e-05</ixy>
          <ixz>-0.000289</ixz>
          <iyy>0.0058</iyy>
          <iyz>0.000808</iyz>
          <izz>0.00103</izz>
        </inertia>
      </inertial>
      <collision name='upper0_collision'>
        <pose frame=''>0 0 -0.1065 0 1.5708 0</pose>
        <geometry>
          <box>
            <size>0.213 0.0245 0.034</size>
          </box>
        </geometry>
        <surface>
          <contact>
            <ode>
              <kp>1e+06</kp>
              <kd>1</kd>
            </ode>
          </contact>
          <friction>
            <ode>
              <mu>0.2</mu>
              <mu2>0.2</mu2>
            </ode>
          </friction>
        </surface>
      </collision>
      <visual name='upper0_visual_visual'>
        <pose frame=''>0 0 0 0 -0 0</pose>
        <geometry>
          <mesh>
            <scale>1 1 1</scale>
            <uri>file:///home/lunarlab/Desktop/quadruped_sim_ws/src/quad-sdk/quad_simulator/go2_description/meshes/thigh.dae</uri>
          </mesh>
        </geometry>
        <material>
          <script>
            <name>Gazebo/DarkGrey</name>
            <uri>file://media/materials/scripts/gazebo.material</uri>
          </script>
        </material>
      </visual>
      <self_collide>0</self_collide>
    </link>

    <joint name='0' type='revolute'>
      <pose relative_to='hip0'>0 0.0955 0 0 -0 0</pose>
      <parent>hip0</parent>
      <child>upper0</child>
      <physics>
        <provide_feedback>true</provide_feedback>
      </physics>
      <axis>
        <xyz>0 1 0</xyz>
        <limit>
          <lower>-1.5708</lower>
          <upper>3.4907</upper>
          <effort>23.7</effort>
          <velocity>30.1</velocity>
        </limit>
        <dynamics>
          <damping>0</damping>
          <friction>0</friction>
          <spring_reference>0</spring_reference>
          <spring_stiffness>0</spring_stiffness>
        </dynamics>
      </axis>
    </joint>
    
    <link name='lower0'>
      <pose relative_to='1'>0 0 0 0 -0 0</pose>
      <inertial>
        <pose frame=''>0.00548 -0.000975 -0.115 0 -0 0</pose>
        <mass>0.154</mass>
        <inertia>
          <ixx>0.00108</ixx>
          <ixy>3.4e-07</ixy>
          <ixz>1.72e-05</ixz>
          <iyy>0.0011</iyy>
          <iyz>8.28e-06</iyz>
          <izz>3.29e-05</izz>
        </inertia>
      </inertial>
      <collision name='lower0_collision'>
        <pose frame=''>0 0 -0.1065 0 1.5708 0</pose>
        <geometry>
          <box>
            <size>0.213 0.016 0.016</size>
          </box>
        </geometry>
        <surface>
          <contact>
            <ode/>
          </contact>
          <friction>
            <ode>
              <mu>0.2</mu>
              <mu2>0.2</mu2>
            </ode>
          </friction>
        </surface>
      </collision>
      <visual name='lower0_visual_visual'>
        <pose frame=''>0 0 0 0 -0 0</pose>
        <geometry>
          <mesh>
            <scale>1 1 1</scale>
            <uri>file:///home/lunarlab/Desktop/quadruped_sim_ws/src/quad-sdk/quad_simulator/go2_description/meshes/calf.dae</uri>
          </mesh>
        </geometry>
      </visual>
      <self_collide>0</self_collide>
    </link>

    <joint name='1' type='revolute'>
      <pose relative_to='upper0'>0 0 -0.213 0 -0 0</pose>
      <parent>upper0</parent>
      <child>lower0</child>
      <physics>
        <provide_feedback>true</provide_feedback>
      </physics2
      <axis>
        <xyz>0 1 0</xyz>
        <limit>
          <lower>-2.7227</lower>
          <upper>-0.83776</upper>
          <effort>35.55</effort>
          <velocity>20.06</velocity>
        </limit>
        <dynamics>
          <damping>0</damping>
          <friction>0</friction>
          <spring_reference>0</spring_reference>
          <spring_stiffness>0</spring_stiffness>
        </dynamics>
      </axis>
    </joint>
    
    <link name='toe0'>
      <pose relative_to='jtoe0'>0 0 0 0 -0 0</pose>
      <inertial>
        <pose frame=''>0 0 0 0 -0 0</pose>
        <mass>0.06</mass>
        <inertia>
          <ixx>9.6e-06</ixx>
          <ixy>0</ixy>
          <ixz>0</ixz>
          <iyy>9.6e-06</iyy>
          <iyz>0</iyz>
          <izz>9.6e-06</izz>
        </inertia>
      </inertial>
      <collision name='toe0_collision'>
        <pose frame=''>0 0 0 0 -0 0</pose>
        <geometry>
          <sphere>
            <radius>0.02</radius>
          </sphere>
        </geometry>
        <surface>
          <contact>
            <ode>
              <kp>1e+06</kp>
              <kd>1</kd>
            </ode>
          </contact>
          <friction>
            <ode>
              <mu>0.6</mu>
              <mu2>0.6</mu2>
            </ode>
          </friction>
        </surface>
      </collision>
      <visual name='toe0_visual_visual'>
        <pose frame=''>0 0 0 0 -0 0</pose>
        <geometry>
          <sphere>
            <radius>0.01</radius>
          </sphere>
        </geometry>
        <material>
          <script>
            <name>Gazebo/DarkGrey</name>
            <uri>file://media/materials/scripts/gazebo.material</uri>
          </script>
        </material>
      </visual>
      <sensor name='toe0_contact' type='contact'>
        <plugin name='toe0_plugin' filename='libgazebo_ros_bumper.so'>
          <alwaysOn>1</alwaysOn>
          <updateRate>500</updateRate>
          <bumperTopicName>gazebo/toe0_contact_state</bumperTopicName>
          <frameName>world</frameName>
        </plugin>
        <contact>
          <collision>toe0_collision</collision>
          <topic>__default_topic__</topic>
        </contact>
        <update_rate>500</update_rate>
      </sensor>
      <self_collide>0</self_collide>
    </link>

    <joint name='jtoe0' type='fixed'>
      <pose relative_to='lower0'>0 0 -0.213 0 -0 0</pose>
      <parent>lower0</parent>
      <child>toe0</child>
      <axis>
        <dynamics>
          <spring_reference>0</spring_reference>
          <spring_stiffness>0</spring_stiffness>
        </dynamics>
        <xyz>0 0 1</xyz>
        <limit>
          <lower>-1e+16</lower>
          <upper>1e+16</upper>
        </limit>
      </axis>
      <physics>
        <ode>
          <limit>
            <cfm>0</cfm>
            <erp>0.2</erp>
          </limit>
        </ode>
      </physics>
    </joint>
    
    <link name='hip1'>
      <pose relative_to='9'>0 0 0 0 -0 0</pose>
      <inertial>
        <pose frame=''>0.0054 0.00194 -0.000105 0 -0 0</pose>
        <mass>0.678</mass>
        <inertia>
          <ixx>0.00048</ixx>
          <ixy>3.01e-06</ixy>
          <ixz>-1.11e-06</ixz>
          <iyy>0.000884</iyy>
          <iyz>-1.42e-06</iyz>
          <izz>0.000596</izz>
        </inertia>
      </inertial>
      <collision name='hip1_collision'>
        <pose frame=''>0 0.0955 0 1.5708 -0 0</pose>
        <geometry>
          <cylinder>
            <length>0.04</length>
            <radius>0.046</radius>
          </cylinder>
        </geometry>
        <surface>
          <contact>
            <ode/>
          </contact>
          <friction>
            <ode>
              <mu>0.2</mu>
              <mu2>0.2</mu2>
            </ode>
          </friction>
        </surface>
      </collision>
      <visual name='hip1_visual_visual'>
        <pose frame=''>0 0 0 3.14159 0 3.14159</pose>
        <geometry>
          <mesh>
            <scale>1 1 1</scale>
            <uri>file:///home/lunarlab/Desktop/quadruped_sim_ws/src/quad-sdk/quad_simulator/go2_description/meshes/hip.dae</uri>
          </mesh>
        </geometry>
        <material>
          <script>
            <name>Gazebo/DarkGrey</name>
            <uri>file://media/materials/scripts/gazebo.material</uri>
          </script>
        </material>
      </visual>
    </link>

    <joint name='9' type='revolute'>
      <pose relative_to='body'>-0.1934 0.0465 0 0 -0 0</pose>
      <parent>body</parent>
      <child>hip1</child>
      <physics>
        <provide_feedback>true</provide_feedback>
      </physics>
      <axis>
        <xyz>1 0 0</xyz>
        <limit>
          <lower>-1.0472</lower>
          <upper>1.0472</upper>
          <effort>23.7</effort>
          <velocity>30.1</velocity>
        </limit>
        <dynamics>
          <damping>0</damping>
          <friction>0</friction>
          <spring_reference>0</spring_reference>
          <spring_stiffness>0</spring_stiffness>
        </dynamics>
      </axis>
    </joint>
    
    <link name='upper1'>
      <pose relative_to='2'>0 0 0 0 -0 0</pose>
      <inertial>
        <pose frame=''>-0.00374 -0.0223 -0.0327 0 -0 0</pose>
        <mass>1.152</mass>
        <inertia>
          <ixx>0.00584</ixx>
          <ixy>8.72e-05</ixy>
          <ixz>-0.000289</ixz>
          <iyy>0.0058</iyy>
          <iyz>0.000808</iyz>
          <izz>0.00103</izz>
        </inertia>
      </inertial>
      <collision name='upper1_collision'>
        <pose frame=''>0 0 -0.1065 0 1.5708 0</pose>
        <geometry>
          <box>
            <size>0.213 0.0245 0.034</size>
          </box>
        </geometry>
        <surface>
          <contact>
            <ode>
              <kp>1e+06</kp>
              <kd>1</kd>
            </ode>
          </contact>
          <friction>
            <ode>
              <mu>0.2</mu>
              <mu2>0.2</mu2>
            </ode>
          </friction>
        </surface>
      </collision>
      <visual name='upper1_visual_visual'>
        <pose frame=''>0 0 0 0 -0 0</pose>
        <geometry>
          <mesh>
            <scale>1 1 1</scale>
            <uri>file:///home/lunarlab/Desktop/quadruped_sim_ws/src/quad-sdk/quad_simulator/go2_description/meshes/thigh.dae</uri>
          </mesh>
        </geometry>
        <material>
          <script>
            <name>Gazebo/DarkGrey</name>
            <uri>file://media/materials/scripts/gazebo.material</uri>
          </script>
        </material>
      </visual>
      <self_collide>0</self_collide>
    </link>

    <joint name='2' type='revolute'>
      <pose relative_to='hip1'>0 0.0955 0 0 -0 0</pose>
      <parent>hip1</parent>
      <child>upper1</child>
      <physics>
        <provide_feedback>true</provide_feedback>
      </physics>
      <axis>
        <xyz>0 1 0</xyz>
        <limit>
          <lower>-1.5708</lower>
          <upper>3.4907</upper>
          <effort>23.7</effort>
          <velocity>30.1</velocity>
        </limit>
        <dynamics>
          <damping>0</damping>
          <friction>0</friction>
          <spring_reference>0</spring_reference>
          <spring_stiffness>0</spring_stiffness>
        </dynamics>
      </axis>
    </joint>
    
    <link name='lower1'>
      <pose relative_to='3'>0 0 0 0 -0 0</pose>
      <inertial>
        <pose frame=''>0.00548 -0.000975 -0.115 0 -0 0</pose>
        <mass>0.154</mass>
        <inertia>
          <ixx>0.00108</ixx>
          <ixy>3.4e-07</ixy>
          <ixz>1.72e-05</ixz>
          <iyy>0.0011</iyy>
          <iyz>8.28e-06</iyz>
          <izz>3.29e-05</izz>
        </inertia>
      </inertial>
      <collision name='lower1_collision'>
        <pose frame=''>0 0 -0.1065 0 1.5708 0</pose>
        <geometry>
          <box>
            <size>0.213 0.016 0.016</size>
          </box>
        </geometry>
        <surface>
          <contact>
            <ode/>
          </contact>
          <friction>
            <ode>
              <mu>0.2</mu>
              <mu2>0.2</mu2>
            </ode>
          </friction>
        </surface>
      </collision>
      <visual name='lower1_visual_visual'>
        <pose frame=''>0 0 0 0 -0 0</pose>
        <geometry>
          <mesh>
            <scale>1 1 1</scale>
            <uri>file:///home/lunarlab/Desktop/quadruped_sim_ws/src/quad-sdk/quad_simulator/go2_description/meshes/calf.dae</uri>
          </mesh>
        </geometry>
      </visual>
      <self_collide>0</self_collide>
    </link>

    <joint name='3' type='revolute'>
      <pose relative_to='upper1'>0 0 -0.213 0 -0 0</pose>
      <parent>upper1</parent>
      <child>lower1</child>
      <physics>
        <provide_feedback>true</provide_feedback>
      </physics>
      <axis>
        <xyz>0 1 0</xyz>
        <limit>
          <lower>-2.7227</lower>
          <upper>-0.83776</upper>
          <effort>35.55</effort>
          <velocity>20.06</velocity>
        </limit>
        <dynamics>
          <damping>0</damping>
          <friction>0</friction>
          <spring_reference>0</spring_reference>
          <spring_stiffness>0</spring_stiffness>
        </dynamics>
      </axis>
    </joint>
    
    <link name='toe1'>
      <pose relative_to='jtoe1'>0 0 0 0 -0 0</pose>
      <inertial>
        <pose frame=''>0 0 0 0 -0 0</pose>
        <mass>0.06</mass>
        <inertia>
          <ixx>9.6e-06</ixx>
          <ixy>0</ixy>
          <ixz>0</ixz>
          <iyy>9.6e-06</iyy>
          <iyz>0</iyz>
          <izz>9.6e-06</izz>
        </inertia>
      </inertial>
      <collision name='toe1_collision'>
        <pose frame=''>0 0 0 0 -0 0</pose>
        <geometry>
          <sphere>
            <radius>0.02</radius>
          </sphere>
        </geometry>
        <surface>
          <contact>
            <ode>
              <kp>1e+06</kp>
              <kd>1</kd>
            </ode>
          </contact>
          <friction>
            <ode>
              <mu>0.6</mu>
              <mu2>0.6</mu2>
            </ode>
          </friction>
        </surface>
      </collision>
      <visual name='toe1_visual_visual'>
        <pose frame=''>0 0 0 0 -0 0</pose>
        <geometry>
          <sphere>
            <radius>0.01</radius>
          </sphere>
        </geometry>
        <material>
          <script>
            <name>Gazebo/DarkGrey</name>
            <uri>file://media/materials/scripts/gazebo.material</uri>
          </script>
        </material>
      </visual>
      <sensor name='toe1_contact' type='contact'>
        <plugin name='toe1_plugin' filename='libgazebo_ros_bumper.so'>
          <alwaysOn>1</alwaysOn>
          <updateRate>500</updateRate>
          <bumperTopicName>gazebo/toe1_contact_state</bumperTopicName>
          <frameName>world</frameName>
        </plugin>
        <contact>
          <collision>toe1_collision</collision>
          <topic>__default_topic__</topic>
        </contact>
        <update_rate>500</update_rate>
      </sensor>
      <self_collide>0</self_collide>
    </link>

    <joint name='jtoe1' type='fixed'>
      <pose relative_to='lower1'>0 0 -0.213 0 -0 0</pose>
      <parent>lower1</parent>
      <child>toe1</child>
      <axis>
        <dynamics>
          <spring_reference>0</spring_reference>
          <spring_stiffness>0</spring_stiffness>
        </dynamics>
        <xyz>0 0 1</xyz>
        <limit>
          <lower>-1e+16</lower>
          <upper>1e+16</upper>
        </limit>
      </axis>
      <physics>
        <ode>
          <limit>
            <cfm>0</cfm>
            <erp>0.2</erp>
          </limit>
        </ode>
      </physics>
    </joint>
    
    <plugin name='gazebo_ros_control' filename='libgazebo_ros_control.so'>
      <robotNamespace>/go2</robotNamespace>
      <robotSimType>gazebo_ros_control/DefaultRobotHWSim</robotSimType>
    </plugin>
    <plugin name='ground_truth_estimator' filename='libground_truth_estimator.so'>
      <updateRateHZ>500.0</updateRateHZ>
    </plugin>
    <plugin name='gazebo_ros_force' filename='libgazebo_ros_force.so'>
      <topicName>/apply_force/trunk</topicName>
      <bodyName>body</bodyName>
      <xyzOffset>0 0 0</xyzOffset>
      <rpyOffset>0 -0 0</rpyOffset>
    </plugin>
    <frame name='imu_joint' attached_to='trunk'>
      <pose frame=''>0 0 0 0 -0 0</pose>
    </frame>
    <frame name='imu_link' attached_to='imu_joint'/>
    <frame name='floating_base' attached_to='body'>
      <pose frame=''>0 0 0 0 -0 0</pose>
    </frame>
    <frame name='trunk' attached_to='floating_base'/>
  </model>
</sdf>